// The Finally Clause #62


const f = () => {
  try {
    let a = 0;
    // console.log(programm);
    console.log("Program ran successful");
    return 
  } catch (error) {
    console.log("This is an error");
    console.log(p);
  } finally {
    console.log("I am a good boy");
    // Close the file
    // Exit the loop
    // Write to the log file
  }
};


f()
console.log("End")